{"uuid": "8445b001-826d-475e-a71a-4806214112ad", "children": ["f25857b5-e3f9-49c4-a04a-bc5ebeb0c7e5"], "befores": [{"name": "browser", "status": "broken", "statusDetails": {"message": "selenium.common.exceptions.WebDriverException: Message: Process unexpectedly closed with status 0\n\n", "trace": "  File \"C:\\Users\\Сергей\\AppData\\Local\\Programs\\Python\\Python312\\Lib\\site-packages\\pluggy\\_callers.py\", line 38, in run_old_style_hookwrapper\n    res = yield\n          ^^^^^\n  File \"C:\\Users\\Сергей\\AppData\\Local\\Programs\\Python\\Python312\\Lib\\site-packages\\pluggy\\_callers.py\", line 139, in _multicall\n    teardown.throw(exception)\n  File \"C:\\Users\\Сергей\\AppData\\Local\\Programs\\Python\\Python312\\Lib\\site-packages\\_pytest\\setuponly.py\", line 36, in pytest_fixture_setup\n    return (yield)\n            ^^^^^\n  File \"C:\\Users\\Сергей\\AppData\\Local\\Programs\\Python\\Python312\\Lib\\site-packages\\pluggy\\_callers.py\", line 121, in _multicall\n    res = hook_impl.function(*args)\n          ^^^^^^^^^^^^^^^^^^^^^^^^^\n  File \"C:\\Users\\Сергей\\AppData\\Local\\Programs\\Python\\Python312\\Lib\\site-packages\\_pytest\\fixtures.py\", line 1195, in pytest_fixture_setup\n    result = call_fixture_func(fixturefunc, request, kwargs)\n             ^^^^^^^^^^^^^^^^^^^^^^^^^^^^^^^^^^^^^^^^^^^^^^^\n  File \"C:\\Users\\Сергей\\AppData\\Local\\Programs\\Python\\Python312\\Lib\\site-packages\\_pytest\\fixtures.py\", line 922, in call_fixture_func\n    fixture_result = next(generator)\n                     ^^^^^^^^^^^^^^^\n  File \"C:\\Users\\Сергей\\Desktop\\Python\\DZ10\\Autotest for online store\\test_saucedemo.py\", line 33, in browser\n    driver = webdriver.Firefox(\n             ^^^^^^^^^^^^^^^^^^\n  File \"C:\\Users\\Сергей\\AppData\\Local\\Programs\\Python\\Python312\\Lib\\site-packages\\selenium\\webdriver\\firefox\\webdriver.py\", line 72, in __init__\n    super().__init__(command_executor=executor, options=options)\n  File \"C:\\Users\\Сергей\\AppData\\Local\\Programs\\Python\\Python312\\Lib\\site-packages\\selenium\\webdriver\\remote\\webdriver.py\", line 263, in __init__\n    self.start_session(capabilities)\n  File \"C:\\Users\\Сергей\\AppData\\Local\\Programs\\Python\\Python312\\Lib\\site-packages\\selenium\\webdriver\\remote\\webdriver.py\", line 366, in start_session\n    response = self.execute(Command.NEW_SESSION, caps)[\"value\"]\n               ^^^^^^^^^^^^^^^^^^^^^^^^^^^^^^^^^^^^^^^\n  File \"C:\\Users\\Сергей\\AppData\\Local\\Programs\\Python\\Python312\\Lib\\site-packages\\selenium\\webdriver\\remote\\webdriver.py\", line 458, in execute\n    self.error_handler.check_response(response)\n  File \"C:\\Users\\Сергей\\AppData\\Local\\Programs\\Python\\Python312\\Lib\\site-packages\\selenium\\webdriver\\remote\\errorhandler.py\", line 232, in check_response\n    raise exception_class(message, screen, stacktrace)\n"}, "start": 1755386279250, "stop": 1755386290558}], "start": 1755386279250, "stop": 1755386290951}